<mujoco model="BHAM">
    <option viscosity = "1"/>
    <worldbody>
        <camera fovy="75" name="BHAM.fixed2" pos="1 -1 1" quat='0.924 0.383 0 0' />
        <camera fovy="75" name="BHAM.fixed" pos="1 0 1" euler="0 0 0" />
        
        <body childclass="BHAM" name="BHAM.floor" pos="0 0 0">
            <inertial diaginertia="0 0 0" mass="0" pos="0 0 0" />
            <geom pos="0 0 0" rgba="1 1 0 1" size="0.5 0.5 0.025" type="plane" friction="0" />
        </body>
        <body childclass="BHAM" name="BHAM.forearm" pos="0 0 0">
            <inertial diaginertia="3.35103e-06 3.35103e-06 5.02655e-06" mass="1" pos="0 0 0" />
            <joint name="BHAM.ARTx" pos="0 0 0" axis="1 0 0" type="slide" range="-2.0 2.0"           damping="80"/>
            <joint name="BHAM.ARTy" pos="0 0 0" axis="0 1 0" type="slide" range="-2 2"          damping="80"/>
            <joint name="BHAM.ARTz" pos="0 0 0" axis="0 0 1" type="slide" range="-1 1"          damping="80"/>
            <joint name="BHAM.ARRx" pos="0 0 0" axis="1 0 0" type="hinge" range="-3.14159 3.14159"  damping="1"  />
            <joint name="BHAM.ARRy" pos="0 0 0" axis="0 1 0" type="hinge" range="-3.14159 3.14159"  damping="1"  />
            <joint name="BHAM.ARRz" pos="0 0 0" axis="0 0 1" type="hinge" range="-3.14159 3.14159"  damping="1"  />
            <body name="BHAM.palm" pos="0 0 0" quat="1 0 0 0">
                <inertial diaginertia="0.00149093 0.00115965 0.00102401" mass="0.801064" pos="-0.00433581 0.0278728 -0.00961453" quat="0.0172605 0.553611 0.101044 0.826443" />
                <geom conaffinity="0" contype="0" mass="0" mesh="BHAM.righthandbase" name="BHAM.righthandbase" type="mesh" />
                <geom mesh="BHAM.palm1" mass="0.9" name="BHAM.palm1" rgba="0 0 0 0" type="mesh" />
                <geom mesh="BHAM.palm2" mass="0.2485" name="BHAM.palm2" rgba="0 0 0 0" type="mesh" />
                <body name="BHAM.thumb0" pos="0 0 0">
                    <inertial diaginertia="1.20581e-5 9.65467e-6 4.22719e-6" mass="0.0176" pos="0.034312 0.0535929 0.0406575" quat="0 0 0 1" />
                     <!-- 0.851839 0.426132 0.292423 -0.0852712 -->
                    <joint axis="0.549586 -0.456218 0.699872" name="BHAM.thumb_ABD" pos="0.036754 0.056714 0.04474" range="-1 1" />
                    <geom mesh="BHAM.thumb_basecover" name="BHAM.thumb_basecover" type="mesh" />
                    <body name="BHAM.thumb1" pos="0 0 0">
                        <inertial diaginertia="2.47814e-5 2.07636e-5 9.90171e-6" mass="0.0232" pos="0.0437866 0.0847763 0.0603761" quat="0.601855 0.742582 0.23387 -0.177897" />
                        <joint axis="-0.8142 -0.104803 0.571047" name="BHAM.thumb_IN" pos="0.036754 0.056714 0.04474" range="-0.1 0.8" />
                        <geom mesh="BHAM.thumb_proximalp" name="BHAM.thumb_proximalp" type="mesh" />
                        <body name="BHAM.thumb2" pos="0 0 0">
                            <inertial diaginertia="1.17398e-5 1.17052e-5 7.00527e-6" mass="0.0158" pos="0.0503579 0.113562 0.0743528" quat="0.583097 0.776931 -0.222353 0.0832728" />
                            <joint axis="-0.8142 -0.104803 0.571047" name="BHAM.thumb_OUT" pos="0.046615 0.10503 0.06708" range="0.087266 1.2217" />
                            <geom mesh="BHAM.thumb_middlep" name="BHAM.thumb_middlep" type="mesh" />
                            <body name="BHAM.thumb3" pos="0 0 0">
                                <inertial diaginertia="9.09431e-6 8.84306e-6 5.34772e-6" mass="0.0137" pos="0.0539685 0.137464 0.0841294" quat="0.539226 0.69153 -0.410629 0.249812" />
                                <joint axis="-0.8142 -0.104803 0.571047" name="BHAM.thumb_TIP" pos="0.050016 0.12692 0.078691" range="0.087266 1.2217" />
                                <geom mesh="BHAM.thumb_distalp" name="BHAM.thumb_distalp" type="mesh" />
                            </body>
                        </body>
                    </body>
                </body>
                <body name="BHAM.fore0" pos="0 0 0">
                    <inertial diaginertia="1.20581e-5 9.65469e-6 4.22719e-6" mass="0.0176" pos="0.0291766 0.0808036 -0.0172436" quat="0.97727 -0.207392 -0.0430513 -0.00881044" />
                    <joint axis="0.087156 0 -0.996195" name="BHAM.fore_ABD" pos="0.029434 0.08577 -0.020007" range="-0.2618 0.2618" />
                    <geom mesh="BHAM.fore_basecover" name="BHAM.fore_basecover" type="mesh" />
                    <body name="BHAM.fore1" pos="0 0 0">
                        <inertial diaginertia="2.47814e-5 2.07636e-5 9.90172e-6" mass="0.0232" pos="0.0298699 0.118593 -0.0219824" quat="0.587334 0.807596 -0.044716 0.0287853" />
                        <joint axis="0.996195 0 0.087156" name="BHAM.fore_IN" pos="0.029434 0.08577 -0.020007" range="0.087266 1.0471" />
                        <geom mesh="BHAM.fore_proximalp" name="BHAM.fore_proximalp" type="mesh" />
                        <body name="BHAM.fore2" pos="0 0 0">
                            <inertial diaginertia="1.17398e-5 1.17052e-5 7.00528e-6" mass="0.0158" pos="0.0295082 0.151257 -0.022276" quat="0.538583 0.638827 -0.403273 0.373094" />
                            <joint axis="0.996195 0 0.087156" name="BHAM.fore_OUT" pos="0.029014 0.1399 -0.019052" range="0.087266 1.2217" />
                            <geom mesh="BHAM.fore_middlep" name="BHAM.fore_middlep" type="mesh" />
                            <body name="BHAM.fore3" pos="0 0 0">
                                <inertial diaginertia="9.09435e-6 8.84309e-6 5.34772e-6" mass="0.0137" pos="0.0294646 0.17725 -0.0201939" quat="0.416648 0.511765 -0.56981 0.489712" />
                                <joint axis="0.996195 0 0.087156" name="BHAM.fore_TIP" pos="0.030576 0.16486 -0.018924" range="0.087266 1.2217" />
                                <geom mesh="BHAM.fore_distalp" name="BHAM.fore_distalp" type="mesh" />
                            </body>
                        </body>
                    </body>
                </body>
                <body name="BHAM.middle0" pos="0 0 0">
                    <inertial diaginertia="1.20581e-5 9.65469e-6 4.2272e-6" mass="0.0176" pos="0.00261974 0.0908037 -0.0184136" quat="0.978218 -0.20758 -0.000382091 0.000244214" />
                    <joint axis="0 0 -1" name="BHAM.middle_ABD" pos="0.0026354 0.09577 -0.021189" range="-0.2618 0.2618" />
                    <geom mesh="BHAM.middle_basecover" name="BHAM.middle_basecover" type="mesh" />
                    <body name="BHAM.middle1" pos="0 0 0">
                        <inertial diaginertia="2.47814e-5 2.07636e-5 9.90172e-6" mass="0.0232" pos="0.00289744 0.128593 -0.0231948" quat="0.588725 0.808083 -0.0190541 -0.00646947" />
                        <joint axis="1 0 0" name="BHAM.middle_IN" pos="0.0026354 0.09577 -0.021189" range="0.087266 1.0471" />
                        <geom mesh="BHAM.middle_proximalp" name="BHAM.middle_proximalp" type="mesh" />
                        <body name="BHAM.middle2" pos="0 0 0">
                            <inertial diaginertia="1.17397e-5 1.17051e-5 7.00528e-6" mass="0.0158" pos="0.00251156 0.161257 -0.0234557" quat="0.555649 0.654479 -0.379419 0.344894" />
                            <joint axis="1 0 0" name="BHAM.middle_OUT" pos="0.0023 0.1499 -0.020201" range="0.087266 1.2217" />
                            <geom mesh="BHAM.middle_middlep" name="BHAM.middle_middlep" type="mesh" />
                            <body name="BHAM.middle3" pos="0 0 0">
                                <inertial diaginertia="9.09435e-6 8.8431e-6 5.34772e-6" mass="0.0137" pos="0.00264958 0.18725 -0.0213778" quat="0.441105 0.532638 -0.551095 0.466924" />
                                <joint axis="1 0 0" name="BHAM.middle_TIP" pos="0.003867 0.17486 -0.02021" range="0.087266 1.2217" />
                                <geom mesh="BHAM.middle_distalp" name="BHAM.middle_distalp" type="mesh" />
                                <site name="mid_finger_center" pos="0.003867 0.17486 -0.02021"/>
                            </body>
                        </body>
                    </body>
                </body>
                <body name="BHAM.ring0" pos="0 0 0">
                    <inertial diaginertia="1.20581e-5 9.6547e-6 4.2272e-6" mass="0.0176" pos="-0.023938 0.0856037 -0.0172645" quat="0.977304 -0.207372 0.0422874 0.0092984" />
                    <joint axis="-0.0774016 0 -0.997" name="BHAM.ring_ABD" pos="-0.024164 0.09057 -0.020031" range="-0.2618 0.2618" />
                    <geom mesh="BHAM.ring_basecover" name="BHAM.ring_basecover" type="mesh" />
                    <body name="BHAM.ring1" pos="0 0 0">
                        <inertial diaginertia="2.47814e-5 2.07636e-5 9.90172e-6" mass="0.0232" pos="-0.0240781 0.123393 -0.0220517" quat="0.588996 0.807031 0.0066435 -0.0417111" />
                        <joint axis="0.997 0 -0.0774016" name="BHAM.ring_IN" pos="-0.024164 0.09057 -0.020031" range="0.087266 1.0471" />
                        <geom mesh="BHAM.ring_proximalp" name="BHAM.ring_proximalp" type="mesh" />
                        <body name="BHAM.ring2" pos="0 0 0">
                            <inertial diaginertia="1.17397e-5 1.17051e-5 7.00528e-6" mass="0.0158" pos="-0.0244852 0.156057 -0.022278" quat="0.571688 0.668919 -0.354786 0.315986" />
                            <joint axis="0.997 0 -0.0774016" name="BHAM.ring_OUT" pos="-0.024412 0.1447 -0.019017" range="0.087266 1.2217" />
                            <geom mesh="BHAM.ring_middlep" name="BHAM.ring_middlep" type="mesh" />
                            <body name="BHAM.ring3" pos="0 0 0">
                                <inertial diaginertia="9.09435e-6 8.8431e-6 5.34772e-6" mass="0.0137" pos="-0.0241666 0.18205 -0.02022" quat="0.464721 0.552497 -0.531331 0.443248" />
                                <joint axis="0.997 0 -0.0774016" name="BHAM.ring_TIP" pos="-0.022852 0.16966 -0.019162" range="0.087266 1.2217" />
                                <geom mesh="BHAM.ring_distalp" name="BHAM.ring_distalp" type="mesh" />
                            </body>
                        </body>
                    </body>
                </body>
                <body name="BHAM.little0" pos="0 0 0">
                    <inertial diaginertia="1.20581e-5 9.65468e-6 4.22719e-6" mass="0.0176" pos="-0.0502945 0.0666036 -0.0138051" quat="0.97453 -0.206766 0.0848757 0.018333" />
                    <joint axis="-0.166745 0 -0.986" name="BHAM.little_ABD" pos="-0.050761 0.07157 -0.016541" range="-0.2618 0.2618" />
                    <geom mesh="BHAM.little_basecover" name="BHAM.little_basecover" type="mesh" />
                    <body name="BHAM.little1" pos="0 0 0">
                        <inertial diaginertia="2.47814e-5 2.07635e-5 9.90174e-6" mass="0.0232" pos="-0.0508513 0.104393 -0.0185619" quat="0.588146 0.804443 0.0323287 -0.0768729" />
                        <joint axis="0.986 0 -0.166745" name="BHAM.little_IN" pos="-0.050761 0.07157 -0.016541" range="0.087266 1.0471" />
                        <geom mesh="BHAM.little_proximalp" name="BHAM.little_proximalp" type="mesh" />
                        <body name="BHAM.little2" pos="0 0 0">
                            <inertial diaginertia="1.17397e-5 1.17051e-5 7.00528e-6" mass="0.0158" pos="-0.0512766 0.137057 -0.0187519" quat="0.586633 0.682081 -0.329479 0.28648" />
                            <joint axis="0.986 0 -0.166745" name="BHAM.little_OUT" pos="-0.05092 0.1257 -0.015509" range="0.087266 1.2217" />
                            <geom mesh="BHAM.little_middlep" name="BHAM.little_middlep" type="mesh" />
                            <body name="BHAM.little3" pos="0 0 0">
                                <inertial diaginertia="9.09435e-6 8.84309e-6 5.34772e-6" mass="0.0137" pos="-0.0507799 0.16305 -0.0167295" quat="0.487456 0.571303 -0.510555 0.418728" />
                                <joint axis="0.986 0 -0.166745" name="BHAM.little_TIP" pos="-0.049378 0.15066 -0.01579" range="0.087266 1.2217" />
                                <geom mesh="BHAM.little_distalp" name="BHAM.little_distalp" type="mesh" />
                            </body>
                        </body>
                    </body>
                </body>
            </body>
        </body>
    </worldbody>
    <compiler angle="radian" meshdir="./"/>
    <option apirate="50" cone="elliptic" impratio="1.75" integrator="RK4" iterations="50" tolerance="1e-10" />
    <size nconmax="500" njmax="5000" nstack="500000" />
    <statistic center="0 -0.2 0.2" extent="1" />
    <default class="main">
        <default class="BHAM">
            <joint armature="0.001" damping="0.2" limited="true" />
            <geom condim="4" friction="1 0.005 0.005" group="1" material="BHAM.MatMesh" rgba="0.44 0.54 0.565 1" solref="0.008 1" />
            <site group="3" material="BHAM.MatTouch" type="ellipsoid" />
            <general biasprm="0 -1 0 0 0 0 0 0 0 0" biastype="affine" ctrllimited="true" forcelimited="true" forcerange="-1.25 1.25" />
        </default>
        <default class="IMU">
            <site group="4" material="BHAM.MatIMU" type="box" />
        </default>
        <default class="free">
            <joint type="free" />
        </default>
    </default>
    <asset>
        <texture builtin="gradient" height="600" rgb1="0.4 0.6 0.8" rgb2="0 0 0" type="skybox" width="100" />
        <texture builtin="checker" height="100" name="BHAM.groundplane" rgb1="0.2 0.3 0.4" rgb2="0.1 0.2 0.3" type="2d" width="100" />
        <material name="BHAM.MatTouch" rgba="0.3 0.9 0.3 0.3" />
        <material name="BHAM.MatIMU" rgba="0.1 0.1 0.9 1" />
        <material name="BHAM.MatMesh" rgba="0.6 0.6 0.6 1" />
        <mesh file="dlr_mesh/righthandbase.stl" name="BHAM.righthandbase" />
        <mesh file="dlr_mesh/palm_1_cvx.stl" name="BHAM.palm1" />
        <mesh file="dlr_mesh/palm_2_cvx.stl" name="BHAM.palm2" />
        <mesh file="dlr_mesh/fore_basecover.stl" name="BHAM.fore_basecover" />
        <mesh file="dlr_mesh/fore_distalp.stl" name="BHAM.fore_distalp" />
        <mesh file="dlr_mesh/fore_middlep.stl" name="BHAM.fore_middlep" />
        <mesh file="dlr_mesh/fore_proximalp.stl" name="BHAM.fore_proximalp" />
        <mesh file="dlr_mesh/little_basecover.stl" name="BHAM.little_basecover" />
        <mesh file="dlr_mesh/little_distalp.stl" name="BHAM.little_distalp" />
        <mesh file="dlr_mesh/little_middlep.stl" name="BHAM.little_middlep" />
        <mesh file="dlr_mesh/little_proximalp.stl" name="BHAM.little_proximalp" />
        <mesh file="dlr_mesh/middle_basecover.stl" name="BHAM.middle_basecover" />
        <mesh file="dlr_mesh/middle_distalp.stl" name="BHAM.middle_distalp" />
        <mesh file="dlr_mesh/middle_middlep.stl" name="BHAM.middle_middlep" />
        <mesh file="dlr_mesh/middle_proximalp.stl" name="BHAM.middle_proximalp" />
        <mesh file="dlr_mesh/ring_basecover.stl" name="BHAM.ring_basecover" />
        <mesh file="dlr_mesh/ring_distalp.stl" name="BHAM.ring_distalp" />
        <mesh file="dlr_mesh/ring_middlep.stl" name="BHAM.ring_middlep" />
        <mesh file="dlr_mesh/ring_proximalp.stl" name="BHAM.ring_proximalp" />
        <mesh file="dlr_mesh/thumb_basecover.stl" name="BHAM.thumb_basecover" />
        <mesh file="dlr_mesh/thumb_distalp.stl" name="BHAM.thumb_distalp" />
        <mesh file="dlr_mesh/thumb_middlep.stl" name="BHAM.thumb_middlep" />
        <mesh file="dlr_mesh/thumb_proximalp.stl" name="BHAM.thumb_proximalp" />
    </asset>
    <contact>
        <exclude body1="BHAM.palm" body2="BHAM.thumb1" />
        <exclude body1="BHAM.palm" body2="BHAM.fore1" />
        <exclude body1="BHAM.palm" body2="BHAM.middle1" />
        <exclude body1="BHAM.palm" body2="BHAM.ring1" />
        <exclude body1="BHAM.palm" body2="BHAM.little1" />
        <exclude body1="BHAM.floor" body2="BHAM.thumb1" />
        <exclude body1="BHAM.floor" body2="BHAM.fore1" />
        <exclude body1="BHAM.floor" body2="BHAM.middle1" />
        <exclude body1="BHAM.floor" body2="BHAM.ring1" />
        <exclude body1="BHAM.floor" body2="BHAM.little1" />
        <exclude body1="BHAM.floor" body2="BHAM.thumb2" />
        <exclude body1="BHAM.floor" body2="BHAM.fore2" />
        <exclude body1="BHAM.floor" body2="BHAM.middle2" />
        <exclude body1="BHAM.floor" body2="BHAM.ring2" />
        <exclude body1="BHAM.floor" body2="BHAM.little2" />
        <exclude body1="BHAM.floor" body2="BHAM.thumb3" />
        <exclude body1="BHAM.floor" body2="BHAM.fore3" />
        <exclude body1="BHAM.floor" body2="BHAM.middle3" />
        <exclude body1="BHAM.floor" body2="BHAM.ring3" />
        <exclude body1="BHAM.floor" body2="BHAM.little3" />
        <exclude body1="BHAM.floor" body2="BHAM.palm" />
        <exclude body1="BHAM.floor" body2="BHAM.forearm" />
    </contact>
    <equality>
        <joint joint1="BHAM.thumb_OUT" joint2="BHAM.thumb_TIP" polycoef="0 1 0 0 0" />
        <joint joint1="BHAM.fore_OUT" joint2="BHAM.fore_TIP" polycoef="0 1 0 0 0" />
        <joint joint1="BHAM.middle_OUT" joint2="BHAM.middle_TIP" polycoef="0 1 0 0 0" />
        <joint joint1="BHAM.ring_OUT" joint2="BHAM.ring_TIP" polycoef="0 1 0 0 0" />
        <joint joint1="BHAM.little_OUT" joint2="BHAM.little_TIP" polycoef="0 1 0 0 0" />
    </equality>
    <actuator>
        <position class="BHAM" ctrlrange="-2.0 2.0"          joint="BHAM.ARTx"       forcerange="-100 100"    kp="3000"  name="BHAM.A_ARTx" />
        <position class="BHAM" ctrlrange="-2.0 2.0"         joint="BHAM.ARTy"       forcerange="-100 100"    kp="3000"  name="BHAM.A_ARTy" />
        <position class="BHAM" ctrlrange="-1 1"              joint="BHAM.ARTz"       forcerange="-100 100"    kp="3000"  name="BHAM.A_ARTz" />
        <position class="BHAM" ctrlrange="-3.14159 3.14159" joint="BHAM.ARRx"       forcerange="-100 100"    kp="30"    name="BHAM.A_ARRx" />
        <position class="BHAM" ctrlrange="-3.14159 3.14159" joint="BHAM.ARRy"       forcerange="-100 100"    kp="30"    name="BHAM.A_ARRy" />
        <position class="BHAM" ctrlrange="-3.14159 3.14159" joint="BHAM.ARRz"       forcerange="-100 100"    kp="30"    name="BHAM.A_ARRz" />
        <position class="BHAM" ctrlrange="-3.14159 3.14159"   joint="BHAM.thumb_ABD" forcerange="-5 5"    kp="2000"  name="BHAM.A_thumb_ABD" />
        <position class="BHAM" ctrlrange="-3.14159 3.14159"  joint="BHAM.thumb_IN"   forcerange="-5 5"    kp="2000"  name="BHAM.A_thumb_IN" />
        <position class="BHAM" ctrlrange="-3.14159 3.14159"  joint="BHAM.thumb_OUT"  forcerange="-5 5"    kp="2000"  name="BHAM.A_thumb_OUT" />
        <position class="BHAM" ctrlrange="-0.2618 0.2618"   joint="BHAM.fore_ABD"    forcerange="-5 5"    kp="2000"  name="BHAM.A_fore_ABD" />
        <position class="BHAM" ctrlrange="0.087266 1.0471"  joint="BHAM.fore_IN"     forcerange="-5 5"    kp="2000"  name="BHAM.A_fore_IN" />
        <position class="BHAM" ctrlrange="0.087266 1.2217"  joint="BHAM.fore_OUT"    forcerange="-5 5"    kp="2000"  name="BHAM.A_fore_OUT" />
        <position class="BHAM" ctrlrange="-0.2618 0.2618"   joint="BHAM.middle_ABD"  forcerange="-5 5"    kp="2000"  name="BHAM.A_middle_ABD" />
        <position class="BHAM" ctrlrange="0.087266 1.0471"  joint="BHAM.middle_IN"   forcerange="-5 5"    kp="2000"  name="BHAM.A_middle_IN" />
        <position class="BHAM" ctrlrange="0.087266 1.2217"  joint="BHAM.middle_OUT"  forcerange="-5 5"    kp="2000"  name="BHAM.A_middle_OUT" />
        <position class="BHAM" ctrlrange="-0.2618 0.2618"   joint="BHAM.ring_ABD"    forcerange="-5 5"    kp="2000"  name="BHAM.A_ring_ABD" />
        <position class="BHAM" ctrlrange="0.087266 1.0471"  joint="BHAM.ring_IN"     forcerange="-5 5"    kp="2000"  name="BHAM.A_ring_IN" />
        <position class="BHAM" ctrlrange="0.087266 1.2217"  joint="BHAM.ring_OUT"    forcerange="-5 5"    kp="2000"  name="BHAM.A_ring_OUT" />
        <position class="BHAM" ctrlrange="-0.2618 0.2618"   joint="BHAM.little_ABD"  forcerange="-5 5"    kp="2000"  name="BHAM.A_little_ABD" />
        <position class="BHAM" ctrlrange="0.087266 1.0471"  joint="BHAM.little_IN"   forcerange="-5 5"    kp="2000"  name="BHAM.A_little_IN" />
        <position class="BHAM" ctrlrange="0.087266 1.2217"  joint="BHAM.little_OUT"  forcerange="-5 5"    kp="2000"  name="BHAM.A_little_OUT" />
    </actuator>
</mujoco>
